#!/usr/bin/env python3
"""
🛡️ Error Handler Servant テストスイート
=====================================

Error Handler（D13）の包括的なテストスイート。
エラー処理、分類、復旧提案、ログ連携をテスト。

Author: Claude Elder
Created: 2025-07-23
"""

import pytest
import asyncio
from typing import Dict, Any, List
import json
from datetime import datetime
import tempfile
from pathlib import Path

# テスト対象をインポート
import sys
import os
sys.path.append(os.path.dirname(os.path.dirname(os.path.dirname(os.path.abspath(__file__)))))

from src.elder_tree.servants.dwarf_workshop.error_handler import ErrorHandlerServant


class TestErrorHandlerServant:
    pass


"""Error Handler Servantのテストクラス"""
        """Error Handlerインスタンスを作成"""
        return ErrorHandlerServant()
        
    @pytest.fixture
    def sample_errors(self):
        pass

        """テスト用エラーサンプル""" {
                "type": "SyntaxError",
                "message": "invalid syntax",
                "file": "test.py",
                "line": 42,
                "traceback": "Traceback (most recent call last):\n  File \"test.py\", line 42\n    print(\"hello\n    ^\nSyntaxError: invalid syntax"
            },
            "runtime_error": {
                "type": "RuntimeError",
                "message": "connection refused",
                "component": "database",
                "severity": "critical"
            },
            "validation_error": {
                "type": "ValidationError",
                "message": "email field is required",
                "field": "email",
                "input": {"name": "test"}
            }
        }
        
    # Phase 1: エラー分類（Error Classification）
    async def test_classify_error_syntax(self, error_handler, sample_errors):
        pass

    """構文エラーの分類テスト"""
        """実行時エラーの分類テスト"""
        result = await error_handler.classify_error(sample_errors["runtime_error"])
        
        assert result["success"] is True
        assert result["category"] == "runtime"
        assert result["severity"] == "critical"
        assert result["recoverable"] is True
        assert "retry_strategy" in result
        
    async def test_classify_error_validation(self, error_handler, sample_errors):
        pass

        """検証エラーの分類テスト""" エラー復旧提案（Recovery Suggestions）
    async def test_suggest_recovery_syntax(self, error_handler, sample_errors):
        pass

    """構文エラーの復旧提案テスト"""
        """接続エラーの復旧提案テスト"""
        connection_error = {
            "type": "ConnectionError",
            "message": "Failed to connect to database",
            "host": "localhost",
            "port": 5432
        }
        
        result = await error_handler.suggest_recovery(connection_error)
        
        assert result["success"] is True
        suggestions = result["suggestions"]
        assert any("retry" in s["strategy"] for s in suggestions)
        assert any("fallback" in s["strategy"] for s in suggestions)
        assert any("health_check" in s["strategy"] for s in suggestions)
        
    async def test_suggest_recovery_permission(self, error_handler):
        pass

        """権限エラーの復旧提案テスト""" "PermissionError",
            "message": "Permission denied",
            "file": "/etc/config.conf"
        }
        
        result = await error_handler.suggest_recovery(permission_error)
        
        assert result["success"] is True
        suggestions = result["suggestions"]
        assert any("sudo" in s["description"].lower() for s in suggestions)
        assert any("chmod" in s["command"] for s in suggestions if "command" in s)
        
    # Phase 3: エラーパターン学習（Pattern Learning）
    async def test_learn_error_pattern(self, error_handler):
        pass

    """エラーパターン学習テスト""" "ImportError",
                "message": "No module named 'pandas'",
                "context": {"script": "analysis.py"}
            },
            {
                "type": "ImportError",
                "message": "No module named 'numpy'",
                "context": {"script": "compute.py"}
            },
            {
                "type": "ImportError",
                "message": "No module named 'matplotlib'",
                "context": {"script": "visualize.py"}
            }
        ]
        
        # エラーパターンを学習
        for error in errors:
            await error_handler.report_error(error)
            
        # パターン分析
        result = await error_handler.analyze_patterns()
        
        assert result["success"] is True
        assert "patterns" in result
        patterns = result["patterns"]
        assert any(p["type"] == "ImportError" for p in patterns)
        
        # 頻出パターンの提案
        import_pattern = next(p for p in patterns if p["type"] == "ImportError")
        assert import_pattern["count"] >= 3
        assert "bulk_solution" in import_pattern
        assert "pip install" in import_pattern["bulk_solution"]
        
    # Phase 4: 4賢者連携（Four Sages Integration）
    async def test_sage_integration_incident(self, error_handler):
        pass

    """インシデント賢者との連携テスト""" "SystemError",
            "message": "Database connection pool exhausted",
            "severity": "critical",
            "affected_services": ["api", "worker"]
        }
        
        result = await error_handler.escalate_to_sage(critical_error, "incident")
        
        assert result["success"] is True
        assert result["sage"] == "incident"
        assert "incident_id" in result
        assert result["priority"] == "critical"
        
    async def test_sage_integration_knowledge(self, error_handler):
        pass

        """ナレッジ賢者との連携テスト""" "UnknownError",
            "message": "Unexpected behavior in quantum_compute()",
            "context": {"module": "experimental"}
        }
        
        result = await error_handler.consult_sage(unknown_error, "knowledge")
        
        assert result["success"] is True
        assert result["sage"] == "knowledge"
        assert "similar_cases" in result
        assert "recommended_approach" in result
        
    # Phase 5: エラー処理ワークフロー（Error Handling Workflow）
    async def test_complete_error_workflow(self, error_handler):
        pass

    """完全なエラー処理ワークフローテスト""" "RuntimeError",
            "message": "Service unavailable",
            "service": "payment-gateway",
            "timestamp": datetime.now().isoformat()
        }
        
        # 1.0 エラー報告
        report_result = await error_handler.report_error(error)
        assert report_result["success"] is True
        error_id = report_result["error_id"]
        
        # 2.0 エラー分類
        classify_result = await error_handler.classify_error(error)
        assert classify_result["success"] is True
        
        # 3.0 復旧提案
        recovery_result = await error_handler.suggest_recovery(error)
        assert recovery_result["success"] is True
        
        # 4.0 復旧実行
        recovery_action = recovery_result["suggestions"][0]
        execute_result = await error_handler.execute_recovery(error_id, recovery_action)
        assert execute_result["success"] is True
        
        # 5.0 結果確認
        status_result = await error_handler.get_error_status(error_id)
        assert status_result["success"] is True
        assert status_result["status"] in ["resolved", "mitigated", "monitoring"]
        
    # Phase 6: 高度なエラー処理（Advanced Error Handling）
    async def test_cascade_error_handling(self, error_handler):
        pass

    """カスケードエラー処理テスト""" "ConnectionError",
                "message": "Database connection failed",
                "timestamp": "2025-01-01T10:00:00"
            },
            {
                "type": "RuntimeError",
                "message": "Cache sync failed due to DB unavailable",
                "timestamp": "2025-01-01T10:00:05"
            },
            {
                "type": "ServiceError",
                "message": "API service degraded",
                "timestamp": "2025-01-01T10:00:10"
            }
        ]
        
        result = await error_handler.analyze_cascade(cascade_errors)
        
        assert result["success"] is True
        assert result["root_cause"]["type"] == "ConnectionError"
        assert len(result["affected_components"]) >= 3
        assert "recovery_order" in result
        assert result["recovery_order"][0]["component"] == "database"
        
    async def test_error_correlation(self, error_handler):
        pass

            """エラー相関分析テスト"""
            correlated_errors.append({
                "type": "TimeoutError",
                "message": f"Request timeout on endpoint /api/v1/data/{i}",
                "timestamp": base_time.isoformat(),
                "endpoint": f"/api/v1/data/{i}"
            })
            
        result = await error_handler.correlate_errors(correlated_errors)
        
        assert result["success"] is True
        assert result["correlation_found"] is True
        assert result["common_factor"] == "api_overload"
        assert "mitigation_strategy" in result
        
    # Phase 7: パフォーマンステスト
    async def test_high_volume_error_processing(self, error_handler):
        pass

    """大量エラー処理のパフォーマンステスト"""
            errors.append({
                "type": f"Error{i % 10}",
                "message": f"Test error {i}",
                "severity": ["low", "medium", "high", "critical"][i % 4]
            })
            
        start_time = time.time()
        
        # バッチ処理
        result = await error_handler.batch_process_errors(errors)
        
        end_time = time.time()
        processing_time = end_time - start_time
        
        assert result["success"] is True
        assert result["processed_count"] == 1000
        assert processing_time < 5.0  # 5秒以内に処理完了
        assert result["errors_per_second"] > 200  # 200エラー/秒以上
        
    # Phase 8: エラーレポート生成
    async def test_generate_error_report(self, error_handler):
        pass

    """エラーレポート生成テスト""" "DatabaseError",
            "message": "Connection timeout",
            "severity": "high"
        })
        await error_handler.report_error({
            "type": "ValidationError", 
            "message": "Invalid input",
            "severity": "low"
        })
        
        result = await error_handler.generate_report(
            start_date="2025-01-01",
            end_date="2025-01-31",
            format="json"
        )
        
        assert result["success"] is True
        report = result["report"]
        assert "summary" in report
        assert "error_by_type" in report
        assert "error_by_severity" in report
        assert "top_errors" in report
        assert "recommendations" in report


@pytest.mark.asyncio
class TestErrorHandlerIntegration:
    pass

        """Error Handler統合テスト"""
        """Elder Treeシステムとの統合テスト"""
        handler = ErrorHandlerServant()
        
        # Elder Treeメッセージ形式
        message = {
            "action": "handle_error",
            "data": {
                "error": {
                    "type": "IntegrationError",
                    "message": "Failed to sync with external service",
                    "service": "payment-processor"
                },
                "context": {
                    "request_id": "req-123",
                    "user_id": "user-456"
                }
            }
        }
        
        result = await handler.process_elder_message(message)
        
        assert result["success"] is True
        assert "error_id" in result["data"]
        assert "recovery_suggestions" in result["data"]
        assert result["data"]["sage_notified"] is True


if __name__ == "__main__":
    pytest.main(["-v", __file__])