Traceback (most recent call last):
  File "/root/ai_co/workers/pm_worker.py", line 357, in <module>
2025-07-01 16:44:50,063 [PMWorker] INFO: ðŸš€ ã‚¹ã‚±ãƒ¼ãƒªãƒ³ã‚°ç›£è¦–é–‹å§‹
    worker.start()
Exception in thread Thread-1 (monitor_and_scale):
  File "/root/ai_co/workers/pm_worker.py", line 330, in start
Traceback (most recent call last):
    self.start_scaling_monitor()
  File "/usr/lib/python3.12/threading.py", line 1073, in _bootstrap_inner
  File "/root/ai_co/workers/pm_worker.py", line 269, in start_scaling_monitor
    logger.info(f"ðŸ“Š ã‚¹ã‚±ãƒ¼ãƒªãƒ³ã‚°ç›£è¦–ã‚¹ãƒ¬ãƒƒãƒ‰é–‹å§‹ (é–“éš”: {self.check_interval}ç§’)")
                                                          ^^^^^^^^^^^^^^^^^^^
AttributeError: 'PMWorker' object has no attribute 'check_interval'
