Traceback (most recent call last):
  File "/root/ai_co/workers/pm_worker.py", line 358, in <module>
2025-07-01 16:41:15,708 [PMWorker] INFO: ðŸš€ ã‚¹ã‚±ãƒ¼ãƒªãƒ³ã‚°ç›£è¦–é–‹å§‹
Exception in thread Thread-1 (monitor_and_scale):
Traceback (most recent call last):
  File "/usr/lib/python3.12/threading.py", line 1073, in _bootstrap_inner
    worker.start()
  File "/root/ai_co/workers/pm_worker.py", line 331, in start
    self.run()
  File "/usr/lib/python3.12/threading.py", line 1010, in run
    self._target(*self._args, **self._kwargs)
    self.start_scaling_monitor()
  File "/root/ai_co/workers/pm_worker.py", line 226, in monitor_and_scale
  File "/root/ai_co/workers/pm_worker.py", line 270, in start_scaling_monitor
    while self.scaling_enabled:
          ^^^^^^^^^^^^^^^^^^^^
AttributeError: 'PMWorker' object has no attribute 'scaling_enabled'
    logger.info(f"ðŸ“Š ã‚¹ã‚±ãƒ¼ãƒªãƒ³ã‚°ç›£è¦–ã‚¹ãƒ¬ãƒƒãƒ‰é–‹å§‹ (é–“éš”: {self.check_interval}ç§’)")
                                                          ^^^^^^^^^^^^^^^^^^^
AttributeError: 'PMWorker' object has no attribute 'check_interval'
